2025-06-08 10:27:56,187 INFO    MainThread:2012906 [wandb_setup.py:_flush():70] Current SDK version is 0.19.11
2025-06-08 10:27:56,188 INFO    MainThread:2012906 [wandb_setup.py:_flush():70] Configure stats pid to 2012906
2025-06-08 10:27:56,188 INFO    MainThread:2012906 [wandb_setup.py:_flush():70] Loading settings from /home/vcivale/.config/wandb/settings
2025-06-08 10:27:56,188 INFO    MainThread:2012906 [wandb_setup.py:_flush():70] Loading settings from /home/vcivale/prova/Esercitazione_2/wandb/settings
2025-06-08 10:27:56,188 INFO    MainThread:2012906 [wandb_setup.py:_flush():70] Loading settings from environment variables
2025-06-08 10:27:56,188 INFO    MainThread:2012906 [wandb_init.py:setup_run_log_directory():724] Logging user logs to /home/vcivale/prova/Esercitazione_2/wandb/run-20250608_102756-5ekl6uw0/logs/debug.log
2025-06-08 10:27:56,188 INFO    MainThread:2012906 [wandb_init.py:setup_run_log_directory():725] Logging internal logs to /home/vcivale/prova/Esercitazione_2/wandb/run-20250608_102756-5ekl6uw0/logs/debug-internal.log
2025-06-08 10:27:56,188 INFO    MainThread:2012906 [wandb_init.py:monkeypatch_ipython():643] configuring jupyter hooks <wandb.sdk.wandb_init._WandbInit object at 0x7fee51727850>
2025-06-08 10:27:56,189 INFO    MainThread:2012906 [wandb_init.py:init():852] calling init triggers
2025-06-08 10:27:56,189 INFO    MainThread:2012906 [wandb_init.py:init():857] wandb.init called with sweep_config: {}
config: {'checkpoint': 0, 'test': False, 'trial': 5, 'wandb_project': 'CarRacing-v0-PPO', 'start_episode': 0, 'gamma': 0.99, 'clip_param': 0.4, 'ppo_epoch': 10, 'buffer_capacity': 500, 'batch_size': 128, 'seed': 0, 'action_repeat': 4, 'deathThreshold': 2000, 'deathByGreeneryThreshold': 35, 'maxDistance': 100, 'max_episode_steps': 10000, 'valueStackSize': 8, 'actionStack': 0, 'numberOfLasers': 5, 'actionMultiplier': [2.0, 1.0, 1.0], 'actionBias': [-1.0, 0.0, 0.0], 'saveLocation': 'model/distances/train_5/', '_wandb': {}}
2025-06-08 10:27:56,189 INFO    MainThread:2012906 [wandb_init.py:init():893] starting backend
2025-06-08 10:27:56,189 INFO    MainThread:2012906 [wandb_init.py:init():897] sending inform_init request
2025-06-08 10:27:56,194 INFO    MainThread:2012906 [backend.py:_multiprocessing_setup():101] multiprocessing start_methods=fork,spawn,forkserver, using: spawn
2025-06-08 10:27:56,194 INFO    MainThread:2012906 [wandb_init.py:init():907] backend started and connected
2025-06-08 10:27:56,206 INFO    MainThread:2012906 [wandb_run.py:_label_probe_notebook():1376] probe notebook
2025-06-08 10:27:56,207 INFO    MainThread:2012906 [wandb_init.py:init():1005] updated telemetry
2025-06-08 10:27:56,218 INFO    MainThread:2012906 [wandb_init.py:init():1029] communicating run to backend with 90.0 second timeout
2025-06-08 10:27:56,785 INFO    MainThread:2012906 [wandb_init.py:init():1104] starting run threads in backend
2025-06-08 10:27:57,057 INFO    MainThread:2012906 [wandb_run.py:_console_start():2573] atexit reg
2025-06-08 10:27:57,058 INFO    MainThread:2012906 [wandb_run.py:_redirect():2421] redirect: wrap_raw
2025-06-08 10:27:57,058 INFO    MainThread:2012906 [wandb_run.py:_redirect():2490] Wrapping output streams.
2025-06-08 10:27:57,058 INFO    MainThread:2012906 [wandb_run.py:_redirect():2513] Redirects installed.
2025-06-08 10:27:57,061 INFO    MainThread:2012906 [wandb_init.py:init():1150] run started, returning control to user process
2025-06-08 10:49:39,237 WARNING MsgRouterThr:2012906 [router.py:message_loop():63] [no run ID] message_loop has been closed
Traceback (most recent call last):
  File "/home/vcivale/prova/.venv/lib/python3.10/site-packages/wandb/sdk/interface/router_sock.py", line 27, in _read_message
    return self._sock_client.read_server_response(timeout=1)
  File "/home/vcivale/prova/.venv/lib/python3.10/site-packages/wandb/sdk/lib/sock_client.py", line 235, in read_server_response
    data = self._read_packet_bytes(timeout=timeout)
  File "/home/vcivale/prova/.venv/lib/python3.10/site-packages/wandb/sdk/lib/sock_client.py", line 220, in _read_packet_bytes
    raise SockClientClosedError
wandb.sdk.lib.sock_client.SockClientClosedError

The above exception was the direct cause of the following exception:

Traceback (most recent call last):
  File "/home/vcivale/prova/.venv/lib/python3.10/site-packages/wandb/sdk/interface/router.py", line 56, in message_loop
    msg = self._read_message()
  File "/home/vcivale/prova/.venv/lib/python3.10/site-packages/wandb/sdk/interface/router_sock.py", line 29, in _read_message
    raise MessageRouterClosedError from e
wandb.sdk.interface.router.MessageRouterClosedError
2025-06-08 10:49:39,239 INFO    MsgRouterThr:2012906 [mailbox.py:close():129] [no run ID] Closing mailbox, abandoning 1 handles.
2025-06-08 10:49:40,252 ERROR   MainThread:2012906 [redirect.py:_on_write():664] [no run ID] error in stdout callback
Traceback (most recent call last):
  File "/home/vcivale/prova/.venv/lib/python3.10/site-packages/wandb/sdk/lib/redirect.py", line 662, in _on_write
    cb(written_data)
  File "/home/vcivale/prova/.venv/lib/python3.10/site-packages/wandb/sdk/wandb_run.py", line 2494, in <lambda>
    lambda data: self._console_raw_callback("stdout", data),
  File "/home/vcivale/prova/.venv/lib/python3.10/site-packages/wandb/sdk/wandb_run.py", line 406, in wrapper
    return func(self, *args, **kwargs)
  File "/home/vcivale/prova/.venv/lib/python3.10/site-packages/wandb/sdk/wandb_run.py", line 464, in wrapper_fn
    return func(self, *args, **kwargs)
  File "/home/vcivale/prova/.venv/lib/python3.10/site-packages/wandb/sdk/wandb_run.py", line 1639, in _console_raw_callback
    self._backend.interface.publish_output_raw(name, data)
  File "/home/vcivale/prova/.venv/lib/python3.10/site-packages/wandb/sdk/interface/interface.py", line 762, in publish_output_raw
    self._publish_output_raw(o)
  File "/home/vcivale/prova/.venv/lib/python3.10/site-packages/wandb/sdk/interface/interface_shared.py", line 38, in _publish_output_raw
    self._publish(rec)
  File "/home/vcivale/prova/.venv/lib/python3.10/site-packages/wandb/sdk/interface/interface_sock.py", line 39, in _publish
    self._sock_client.send_record_publish(record)
  File "/home/vcivale/prova/.venv/lib/python3.10/site-packages/wandb/sdk/lib/sock_client.py", line 174, in send_record_publish
    self.send_server_request(server_req)
  File "/home/vcivale/prova/.venv/lib/python3.10/site-packages/wandb/sdk/lib/sock_client.py", line 154, in send_server_request
    self._send_message(msg)
  File "/home/vcivale/prova/.venv/lib/python3.10/site-packages/wandb/sdk/lib/sock_client.py", line 151, in _send_message
    self._sendall_with_error_handle(header + data)
  File "/home/vcivale/prova/.venv/lib/python3.10/site-packages/wandb/sdk/lib/sock_client.py", line 130, in _sendall_with_error_handle
    sent = self._sock.send(data)
BrokenPipeError: [Errno 32] Broken pipe
2025-06-08 10:49:41,238 INFO    MainThread:2012906 [wandb_init.py:_post_run_cell_hook():613] [no run ID] resuming backend
2025-06-08 10:49:41,238 ERROR   MainThread:2012906 [redirect.py:_on_write():664] [no run ID] error in stdout callback
Traceback (most recent call last):
  File "/home/vcivale/prova/.venv/lib/python3.10/site-packages/IPython/core/events.py", line 82, in trigger
    func(*args, **kwargs)
  File "/home/vcivale/prova/.venv/lib/python3.10/site-packages/wandb/sdk/wandb_init.py", line 614, in _post_run_cell_hook
    self.backend.interface.publish_resume()
  File "/home/vcivale/prova/.venv/lib/python3.10/site-packages/wandb/sdk/interface/interface.py", line 778, in publish_resume
    self._publish_resume(resume)
  File "/home/vcivale/prova/.venv/lib/python3.10/site-packages/wandb/sdk/interface/interface_shared.py", line 293, in _publish_resume
    self._publish(rec)
  File "/home/vcivale/prova/.venv/lib/python3.10/site-packages/wandb/sdk/interface/interface_sock.py", line 39, in _publish
    self._sock_client.send_record_publish(record)
  File "/home/vcivale/prova/.venv/lib/python3.10/site-packages/wandb/sdk/lib/sock_client.py", line 174, in send_record_publish
    self.send_server_request(server_req)
  File "/home/vcivale/prova/.venv/lib/python3.10/site-packages/wandb/sdk/lib/sock_client.py", line 154, in send_server_request
    self._send_message(msg)
  File "/home/vcivale/prova/.venv/lib/python3.10/site-packages/wandb/sdk/lib/sock_client.py", line 151, in _send_message
    self._sendall_with_error_handle(header + data)
  File "/home/vcivale/prova/.venv/lib/python3.10/site-packages/wandb/sdk/lib/sock_client.py", line 130, in _sendall_with_error_handle
    sent = self._sock.send(data)
BrokenPipeError: [Errno 32] Broken pipe

During handling of the above exception, another exception occurred:

Traceback (most recent call last):
  File "/home/vcivale/prova/.venv/lib/python3.10/site-packages/wandb/sdk/lib/redirect.py", line 662, in _on_write
    cb(written_data)
  File "/home/vcivale/prova/.venv/lib/python3.10/site-packages/wandb/sdk/wandb_run.py", line 2494, in <lambda>
    lambda data: self._console_raw_callback("stdout", data),
  File "/home/vcivale/prova/.venv/lib/python3.10/site-packages/wandb/sdk/wandb_run.py", line 406, in wrapper
    return func(self, *args, **kwargs)
  File "/home/vcivale/prova/.venv/lib/python3.10/site-packages/wandb/sdk/wandb_run.py", line 464, in wrapper_fn
    return func(self, *args, **kwargs)
  File "/home/vcivale/prova/.venv/lib/python3.10/site-packages/wandb/sdk/wandb_run.py", line 1639, in _console_raw_callback
    self._backend.interface.publish_output_raw(name, data)
  File "/home/vcivale/prova/.venv/lib/python3.10/site-packages/wandb/sdk/interface/interface.py", line 762, in publish_output_raw
    self._publish_output_raw(o)
  File "/home/vcivale/prova/.venv/lib/python3.10/site-packages/wandb/sdk/interface/interface_shared.py", line 38, in _publish_output_raw
    self._publish(rec)
  File "/home/vcivale/prova/.venv/lib/python3.10/site-packages/wandb/sdk/interface/interface_sock.py", line 39, in _publish
    self._sock_client.send_record_publish(record)
  File "/home/vcivale/prova/.venv/lib/python3.10/site-packages/wandb/sdk/lib/sock_client.py", line 174, in send_record_publish
    self.send_server_request(server_req)
  File "/home/vcivale/prova/.venv/lib/python3.10/site-packages/wandb/sdk/lib/sock_client.py", line 154, in send_server_request
    self._send_message(msg)
  File "/home/vcivale/prova/.venv/lib/python3.10/site-packages/wandb/sdk/lib/sock_client.py", line 151, in _send_message
    self._sendall_with_error_handle(header + data)
  File "/home/vcivale/prova/.venv/lib/python3.10/site-packages/wandb/sdk/lib/sock_client.py", line 130, in _sendall_with_error_handle
    sent = self._sock.send(data)
BrokenPipeError: [Errno 32] Broken pipe
2025-06-08 10:49:41,248 ERROR   MainThread:2012906 [redirect.py:_on_write():664] [no run ID] error in stdout callback
Traceback (most recent call last):
  File "/home/vcivale/prova/.venv/lib/python3.10/site-packages/IPython/core/events.py", line 82, in trigger
    func(*args, **kwargs)
  File "/home/vcivale/prova/.venv/lib/python3.10/site-packages/wandb/sdk/wandb_init.py", line 614, in _post_run_cell_hook
    self.backend.interface.publish_resume()
  File "/home/vcivale/prova/.venv/lib/python3.10/site-packages/wandb/sdk/interface/interface.py", line 778, in publish_resume
    self._publish_resume(resume)
  File "/home/vcivale/prova/.venv/lib/python3.10/site-packages/wandb/sdk/interface/interface_shared.py", line 293, in _publish_resume
    self._publish(rec)
  File "/home/vcivale/prova/.venv/lib/python3.10/site-packages/wandb/sdk/interface/interface_sock.py", line 39, in _publish
    self._sock_client.send_record_publish(record)
  File "/home/vcivale/prova/.venv/lib/python3.10/site-packages/wandb/sdk/lib/sock_client.py", line 174, in send_record_publish
    self.send_server_request(server_req)
  File "/home/vcivale/prova/.venv/lib/python3.10/site-packages/wandb/sdk/lib/sock_client.py", line 154, in send_server_request
    self._send_message(msg)
  File "/home/vcivale/prova/.venv/lib/python3.10/site-packages/wandb/sdk/lib/sock_client.py", line 151, in _send_message
    self._sendall_with_error_handle(header + data)
  File "/home/vcivale/prova/.venv/lib/python3.10/site-packages/wandb/sdk/lib/sock_client.py", line 130, in _sendall_with_error_handle
    sent = self._sock.send(data)
BrokenPipeError: [Errno 32] Broken pipe

During handling of the above exception, another exception occurred:

Traceback (most recent call last):
  File "/home/vcivale/prova/.venv/lib/python3.10/site-packages/wandb/sdk/lib/redirect.py", line 662, in _on_write
    cb(written_data)
  File "/home/vcivale/prova/.venv/lib/python3.10/site-packages/wandb/sdk/wandb_run.py", line 2494, in <lambda>
    lambda data: self._console_raw_callback("stdout", data),
  File "/home/vcivale/prova/.venv/lib/python3.10/site-packages/wandb/sdk/wandb_run.py", line 406, in wrapper
    return func(self, *args, **kwargs)
  File "/home/vcivale/prova/.venv/lib/python3.10/site-packages/wandb/sdk/wandb_run.py", line 464, in wrapper_fn
    return func(self, *args, **kwargs)
  File "/home/vcivale/prova/.venv/lib/python3.10/site-packages/wandb/sdk/wandb_run.py", line 1639, in _console_raw_callback
    self._backend.interface.publish_output_raw(name, data)
  File "/home/vcivale/prova/.venv/lib/python3.10/site-packages/wandb/sdk/interface/interface.py", line 762, in publish_output_raw
    self._publish_output_raw(o)
  File "/home/vcivale/prova/.venv/lib/python3.10/site-packages/wandb/sdk/interface/interface_shared.py", line 38, in _publish_output_raw
    self._publish(rec)
  File "/home/vcivale/prova/.venv/lib/python3.10/site-packages/wandb/sdk/interface/interface_sock.py", line 39, in _publish
    self._sock_client.send_record_publish(record)
  File "/home/vcivale/prova/.venv/lib/python3.10/site-packages/wandb/sdk/lib/sock_client.py", line 174, in send_record_publish
    self.send_server_request(server_req)
  File "/home/vcivale/prova/.venv/lib/python3.10/site-packages/wandb/sdk/lib/sock_client.py", line 154, in send_server_request
    self._send_message(msg)
  File "/home/vcivale/prova/.venv/lib/python3.10/site-packages/wandb/sdk/lib/sock_client.py", line 151, in _send_message
    self._sendall_with_error_handle(header + data)
  File "/home/vcivale/prova/.venv/lib/python3.10/site-packages/wandb/sdk/lib/sock_client.py", line 130, in _sendall_with_error_handle
    sent = self._sock.send(data)
BrokenPipeError: [Errno 32] Broken pipe
